<?xml version="1.0" encoding="UTF-8"?>
<!-- Generated by org.testng.reporters.JUnitReportReporter -->
<testsuite hostname="PRINHYLTPDL0700" failures="1" tests="3" name="com.utils.TestListener" time="36.101" errors="1" timestamp="14 Aug 2019 05:12:42 GMT" skipped="1">
  <testcase classname="com.utils.TestListener" name="func2" time="0.000">
    <skipped/>
  </testcase> <!-- func2 -->
  <testcase classname="com.utils.TestListener" name="func1" time="11.811">
    <failure message="expected [Imaginea] but found [Pramati]" type="java.lang.AssertionError">
      <![CDATA[java.lang.AssertionError: expected [Imaginea] but found [Pramati]
at org.testng.Assert.fail(Assert.java:96)
at org.testng.Assert.failNotEquals(Assert.java:776)
at org.testng.Assert.assertEqualsImpl(Assert.java:137)
at org.testng.Assert.assertEquals(Assert.java:118)
at org.testng.Assert.assertEquals(Assert.java:453)
at org.testng.Assert.assertEquals(Assert.java:463)
at com.utils.TestListener.func1(TestListener.java:33)
at java.base/jdk.internal.reflect.NativeMethodAccessorImpl.invoke0(Native Method)
at java.base/jdk.internal.reflect.NativeMethodAccessorImpl.invoke(NativeMethodAccessorImpl.java:62)
at java.base/jdk.internal.reflect.DelegatingMethodAccessorImpl.invoke(DelegatingMethodAccessorImpl.java:43)
at java.base/java.lang.reflect.Method.invoke(Method.java:567)
at org.testng.internal.MethodInvocationHelper.invokeMethod(MethodInvocationHelper.java:124)
at org.testng.internal.Invoker.invokeMethod(Invoker.java:583)
at org.testng.internal.Invoker.invokeTestMethod(Invoker.java:719)
at org.testng.internal.Invoker.invokeTestMethods(Invoker.java:989)
at org.testng.internal.TestMethodWorker.invokeTestMethods(TestMethodWorker.java:125)
at org.testng.internal.TestMethodWorker.run(TestMethodWorker.java:109)
at org.testng.TestRunner.privateRun(TestRunner.java:648)
at org.testng.TestRunner.run(TestRunner.java:505)
at org.testng.SuiteRunner.runTest(SuiteRunner.java:455)
at org.testng.SuiteRunner.runSequentially(SuiteRunner.java:450)
at org.testng.SuiteRunner.privateRun(SuiteRunner.java:415)
at org.testng.SuiteRunner.run(SuiteRunner.java:364)
at org.testng.SuiteRunnerWorker.runSuite(SuiteRunnerWorker.java:52)
at org.testng.SuiteRunnerWorker.run(SuiteRunnerWorker.java:84)
at org.testng.TestNG.runSuitesSequentially(TestNG.java:1208)
at org.testng.TestNG.runSuitesLocally(TestNG.java:1137)
at org.testng.TestNG.runSuites(TestNG.java:1049)
at org.testng.TestNG.run(TestNG.java:1017)
at org.testng.remote.AbstractRemoteTestNG.run(AbstractRemoteTestNG.java:115)
at org.testng.remote.RemoteTestNG.initAndRun(RemoteTestNG.java:251)
at org.testng.remote.RemoteTestNG.main(RemoteTestNG.java:77)
]]>
    </failure>
  </testcase> <!-- func1 -->
  <testcase classname="com.utils.TestListener" name="testcase1" time="24.290">
    <error message="Method com.utils.TestListener.testcase1() didn&#039;t finish within the time-out 200" type="org.testng.internal.thread.ThreadTimeoutException">
      <![CDATA[org.testng.internal.thread.ThreadTimeoutException: Method com.utils.TestListener.testcase1() didn't finish within the time-out 200
at java.base@12.0.2/java.util.concurrent.locks.AbstractQueuedSynchronizer$ConditionObject.doSignalAll(AbstractQueuedSynchronizer.java:1930)
at java.base@12.0.2/java.util.concurrent.locks.AbstractQueuedSynchronizer$ConditionObject.signalAll(AbstractQueuedSynchronizer.java:1999)
at java.base@12.0.2/java.util.concurrent.ThreadPoolExecutor.tryTerminate(ThreadPoolExecutor.java:721)
at java.base@12.0.2/java.util.concurrent.ThreadPoolExecutor.processWorkerExit(ThreadPoolExecutor.java:994)
at java.base@12.0.2/java.util.concurrent.ThreadPoolExecutor.runWorker(ThreadPoolExecutor.java:1142)
at java.base@12.0.2/java.util.concurrent.ThreadPoolExecutor$Worker.run(ThreadPoolExecutor.java:628)
at java.base@12.0.2/java.lang.Thread.run(Thread.java:835)
]]>
    </error>
  </testcase> <!-- testcase1 -->
</testsuite> <!-- com.utils.TestListener -->
